[
    {
        "content": "<p>Hi!<br>\nI getting this outcome error:<br>\n<code>The value provided ('generated') is not in the value set http://hl7.org/fhir/ValueSet/narrative-status|4.6.0 (http://hl7.org/fhir/ValueSet/narrative-status), and a code is required from this value set) (error message = Validation failed)</code><br>\nBut the narrative-status ValueSet has the \"generated\" status. Could you please explain to me why I am getting this error?<br>\nThanks!</p>",
        "id": 266926324,
        "sender_full_name": "Igor",
        "timestamp": 1641383855
    },
    {
        "content": "<p><span class=\"user-mention silent\" data-user-id=\"461242\">Igor</span> has marked this topic as resolved.</p>",
        "id": 266927728,
        "sender_full_name": "Notification Bot",
        "timestamp": 1641384883
    },
    {
        "content": "<p><span class=\"user-mention silent\" data-user-id=\"461242\">Igor</span> has marked this topic as unresolved.</p>",
        "id": 266927774,
        "sender_full_name": "Notification Bot",
        "timestamp": 1641384920
    },
    {
        "content": "<p>Are you getting another error about not being about being able to retrieve the value set?</p>",
        "id": 266935171,
        "sender_full_name": "Daniel Venton",
        "timestamp": 1641389380
    },
    {
        "content": "<p>I am getting error for all value sets:<br>\n<code>{\n  \"resourceType\": \"OperationOutcome\",\n  \"issue\": [\n    {\n      \"severity\": \"error\",\n      \"code\": \"processing\",\n      \"diagnostics\": \"The value provided ('generated') is not in the value set http://hl7.org/fhir/ValueSet/narrative-status|4.6.0 (http://hl7.org/fhir/ValueSet/narrative-status), and a code is required from this value set) (error message = Validation failed)\",\n      \"location\": [\n        \"Parameters.parameter[0].resource.ofType(Patient).text.status\",\n        \"Line 1, Col 291\"\n      ]\n    },\n    {\n      \"severity\": \"error\",\n      \"code\": \"processing\",\n      \"diagnostics\": \"The Coding provided (urn:oid:2.16.840.1.113883.6.238#2106-3) is not in the value set http://hl7.org/fhir/us/core/ValueSet/omb-race-category, and a code is required from this value set.  (error message = Validation failed)\",\n      \"location\": [\n        \"Parameters.parameter[0].resource.ofType(Patient).extension[2].extension[0].value.ofType(Coding)\",\n        \"Line 1, Col 770\"\n      ]\n    },\n    {\n      \"severity\": \"error\",\n      \"code\": \"processing\",\n      \"diagnostics\": \"The value provided ('M') is not in the value set http://hl7.org/fhir/us/core/ValueSet/birthsex (http://hl7.org/fhir/us/core/ValueSet/birthsex), and a code is required from this value set) (error message = Validation failed)\",\n      \"location\": [\n        \"Parameters.parameter[0].resource.ofType(Patient).extension[5].value.ofType(code)\",\n        \"Line 1, Col 1640\"\n      ]\n    }\n  ]\n}</code></p>",
        "id": 266940850,
        "sender_full_name": "Igor",
        "timestamp": 1641392503
    },
    {
        "content": "<p>When you look at the console log, is it showing issues connecting to the terminology server?  (Even if it is, it <em>shouldn't</em> be raising errors like this.  If a terminology isn't available, the validator should be spitting out warnings, not errors... - <span class=\"user-mention\" data-user-id=\"191316\">@Grahame Grieve</span>?)</p>",
        "id": 266978304,
        "sender_full_name": "Lloyd McKenzie",
        "timestamp": 1641410357
    },
    {
        "content": "<p>Something is wrong... how to reproduce?</p>",
        "id": 269525866,
        "sender_full_name": "Grahame Grieve",
        "timestamp": 1643259301
    }
]