[
    {
        "content": "<p>We are running the docker image of inferno and are testing Bulk Data Export. But keep getting this error: \"Error connecting to BDT Service: Timed out reading data from server\". We are not sure if it has to do with our server or the inferno install. It seemed a bit random at first, but it seems Download-01  and Status-03 are more likely to get this error.  Any ideas what's going on here? Thanks in advance.</p>",
        "id": 240621396,
        "sender_full_name": "Matthew Dugal",
        "timestamp": 1622216134
    },
    {
        "content": "<p>Is this Inferno for FHIR? If so, you should be running a docker compose command to launch it.</p>",
        "id": 240647161,
        "sender_full_name": "Merlyn Albery-Speyer",
        "timestamp": 1622228473
    },
    {
        "content": "<p>Yes. We followed the guides on the github page and inferno ran without any major issues for a few test runs.</p>",
        "id": 240653490,
        "sender_full_name": "Matthew Dugal",
        "timestamp": 1622231886
    },
    {
        "content": "<p>I don't recognize \"Download-01\" or \"Status-03\". Are these Inferno tests? I was expecting something like \"BDE-08\" or \"Bulk Data Server returns output with type and url for status complete\" as being what fails for you.</p>\n<p>In general I find the Inputs, Outputs, HTTP Requests, and explanatory links &amp; text give me everything I need to know. Failing that you can always look at the test code under the hood also, e.g.:OIDC-01: <a href=\"https://github.com/onc-healthit/inferno/blob/main/lib/modules/smart/openid_connect_sequence.rb#L83-L108\">https://github.com/onc-healthit/inferno/blob/main/lib/modules/smart/openid_connect_sequence.rb#L83-L108</a>.</p>",
        "id": 240662586,
        "sender_full_name": "Merlyn Albery-Speyer",
        "timestamp": 1622237379
    },
    {
        "content": "<p>You can also run the docker compose without setting it up as a daemon to see it's log activity (or else edit the config.yaml to write to a log file). I've seen sqlite database lock errors before which might be your symptom (I switched to the postgres docker compose variant for that reason).</p>",
        "id": 240662850,
        "sender_full_name": "Merlyn Albery-Speyer",
        "timestamp": 1622237564
    },
    {
        "content": "<p><span class=\"user-mention\" data-user-id=\"191473\">@Matthew Dugal</span> I just tested on <a href=\"https://inferno.healthit.gov/community\">https://inferno.healthit.gov/community</a>. The result looks fine. Are you testing there or using your own server instance? Can you try it again?<br>\n<a href=\"/user_uploads/10155/BG4Sl6Ej4nnmi2qAa7GYD5lM/image.png\">image.png</a></p>\n<div class=\"message_inline_image\"><a href=\"/user_uploads/10155/BG4Sl6Ej4nnmi2qAa7GYD5lM/image.png\" title=\"image.png\"><img src=\"/user_uploads/10155/BG4Sl6Ej4nnmi2qAa7GYD5lM/image.png\"></a></div>",
        "id": 240677991,
        "sender_full_name": "Yunwei Wang",
        "timestamp": 1622254301
    }
]